INFO:root:
Selector: Root
| Action: start_execution
| Action: reinforce_strongest
| Action: interrupt_enemy_spread
| Action: spread_to_closest_enemy_planet
| Action: spread_to_closest_neutral_planet

DEBUG:root:Executing:Selector: Root
DEBUG:root:Executing:Action: start_execution
DEBUG:root:Result: Action: start_execution -> Failure
DEBUG:root:Executing:Action: reinforce_strongest
DEBUG:root:Order:pID: 1 total ships: 100.0 fleet size: 1
ERROR:root:Error in bot.
Traceback (most recent call last):
  File "behavior_tree_bot/bt_bot.py", line 94, in <module>
    do_turn(planet_wars)
  File "behavior_tree_bot/bt_bot.py", line 82, in do_turn
    behavior_tree.execute(planet_wars)
  File "C:\Users\AJmet\Documents\GameAI\BehaviorTrees\behavior_tree_bot\bt_nodes.py", line 8, in logged_fn
    result = fn(self, state)
  File "C:\Users\AJmet\Documents\GameAI\BehaviorTrees\behavior_tree_bot\bt_nodes.py", line 52, in execute
    success = child_node.execute(state)
  File "C:\Users\AJmet\Documents\GameAI\BehaviorTrees\behavior_tree_bot\bt_nodes.py", line 8, in logged_fn
    result = fn(self, state)
  File "C:\Users\AJmet\Documents\GameAI\BehaviorTrees\behavior_tree_bot\bt_nodes.py", line 104, in execute
    return self.action_function(state)
  File "C:\Users\AJmet\Documents\GameAI\BehaviorTrees\behavior_tree_bot\behaviors.py", line 95, in reinforce_strongest
    issue_order(state, by_distance[i].ID, reinforce_target.ID, fleet_size)
  File "C:\Users\AJmet\Documents\GameAI\BehaviorTrees\planet_wars.py", line 25, in issue_order
    stdout.flush()
OSError: [Errno 22] Invalid argument
